<?xml version="1.0" ?>
<robot name="krsti" xmlns:xacro="http://www.ros.org/wiki/xacro">

<xacro:include filename="$(find krsti_description)/urdf/materials.xacro" />
<xacro:include filename="$(find krsti_description)/urdf/krsti.trans" />

<!-- ─── ros2_control ──────────────────────────────────────────────────────── -->
<ros2_control name="GazeboSystem" type="system">
  <hardware>
    <plugin>gz_ros2_control/GazeboSimSystem</plugin>
  </hardware>
  <joint name="Revolute 5">
    <command_interface name="position"/>
    <state_interface name="position"/>
    <state_interface name="velocity"/>
  </joint>
  <joint name="Revolute 6">
    <command_interface name="position"/>
    <state_interface name="position"/>
    <state_interface name="velocity"/>
  </joint>
</ros2_control>

<!-- ─── Gazebo ros2_control plugin ──────────────────────────────────────── -->
<gazebo>
  <plugin filename="gz_ros2_control-system" name="gz_ros2_control::GazeboSimROS2ControlPlugin">
    <parameters>$(find krsti_description)/config/ros2_control.yaml</parameters>
  </plugin>
</gazebo>

<link name="base_link">
  <inertial>
    <origin xyz="0.114155970042646 0.044227959143786 0.238475499685274" rpy="0 0 0"/>
    <mass value="1.58286526308532"/>
    <inertia ixx="0.00269139609632445" iyy="0.00157610698082541" izz="0.00174038472267906" ixy="2.72366021894285e-05" iyz="-6.14136418481577e-05" ixz="0.00016429037708876"/>
  </inertial>
  <visual>
    <origin xyz="0 0 0" rpy="0 0 0"/>
    <geometry>
      <mesh filename="package://krsti_description/meshes/base_link.stl" scale="0.001 0.001 0.001"/>
    </geometry>
    <material name="steel_satin"/>
  </visual>
  <collision>
    <origin xyz="0 0 0" rpy="0 0 0"/>
    <geometry>
      <mesh filename="package://krsti_description/meshes/base_link.stl" scale="0.001 0.001 0.001"/>
    </geometry>
  </collision>
</link>

<link name="pinggang_dey_1">
  <inertial>
    <origin xyz="0.01818136279345424 0.007773592835048616 -0.02977229723433139" rpy="0 0 0"/>
    <mass value="0.853317052043831"/>
    <inertia ixx="0.00141624999175083" iyy="0.000425687673249076" izz="0.00150046519986738" ixy="-0.000413484984204435" iyz="-1.40768977597867e-06" ixz="3.88253036293432e-06"/>
  </inertial>
  <visual>
    <origin xyz="-0.113161 -0.030237 -0.179968" rpy="0 0 0"/>
    <geometry>
      <mesh filename="package://krsti_description/meshes/pinggang_dey_1.stl" scale="0.001 0.001 0.001"/>
    </geometry>
    <material name="steel_satin"/>
  </visual>
  <collision>
    <origin xyz="-0.113161 -0.030237 -0.179968" rpy="0 0 0"/>
    <geometry>
      <mesh filename="package://krsti_description/meshes/pinggang_dey_1.stl" scale="0.001 0.001 0.001"/>
    </geometry>
  </collision>
</link>

<link name="TANGAN_KIRI_v1_1">
  <inertial>
    <origin xyz="-0.015926169875037435 0.10166672029145217 -0.03725231687192104" rpy="0 0 0"/>
    <mass value="1.60594721497916"/>
    <inertia ixx="0.00513673422718611" iyy="0.00152260463477567" izz="0.00442598400166563" ixy="0.000794971657187248" iyz="0.00172014984133328" ixz="-0.000425052476324378"/>
  </inertial>
  <visual>
    <origin xyz="-0.111644 -0.098144 -0.264468" rpy="0 0 0"/>
    <geometry>
      <mesh filename="package://krsti_description/meshes/TANGAN_KIRI_v1_1.stl" scale="0.001 0.001 0.001"/>
    </geometry>
    <material name="steel_satin"/>
  </visual>
  <collision>
    <origin xyz="-0.111644 -0.098144 -0.264468" rpy="0 0 0"/>
    <geometry>
      <mesh filename="package://krsti_description/meshes/TANGAN_KIRI_v1_1.stl" scale="0.001 0.001 0.001"/>
    </geometry>
  </collision>
</link>

<link name="TANGAN_KANAN_v1_1">
  <inertial>
    <origin xyz="0.0024529438556489397 -0.1038660100913621 -0.002625436797309144" rpy="0 0 0"/>
    <mass value="1.60821831472818"/>
    <inertia ixx="0.00494437059714592" iyy="0.000469422273099457" izz="0.00492433483257062" ixy="-0.000241503399601002" iyz="0.000374990667898055" ixz="2.53724918754597e-05"/>
  </inertial>
  <visual>
    <origin xyz="-0.111644 0.007856 -0.264468" rpy="0 0 0"/>
    <geometry>
      <mesh filename="package://krsti_description/meshes/TANGAN_KANAN_v1_1.stl" scale="0.001 0.001 0.001"/>
    </geometry>
    <material name="steel_satin"/>
  </visual>
  <collision>
    <origin xyz="-0.111644 0.007856 -0.264468" rpy="0 0 0"/>
    <geometry>
      <mesh filename="package://krsti_description/meshes/TANGAN_KANAN_v1_1.stl" scale="0.001 0.001 0.001"/>
    </geometry>
  </collision>
</link>

<link name="KAKI_KIRI_v1_1">
  <inertial>
    <origin xyz="-0.01897194985300399 0.006903344513362164 -0.12261055457674068" rpy="0 0 0"/>
    <mass value="2.4887596284048"/>
    <inertia ixx="0.0135919132518658" iyy="0.0141525361256383" izz="0.0014564621590917" ixy="0.000241625619342864" iyz="0.000422413350816654" ixz="-0.000894410524455147"/>
  </inertial>
  <visual>
    <origin xyz="-0.15152 -0.089731 -0.128968" rpy="0 0 0"/>
    <geometry>
      <mesh filename="package://krsti_description/meshes/KAKI_KIRI_v1_1.stl" scale="0.001 0.001 0.001"/>
    </geometry>
    <material name="steel_satin"/>
  </visual>
  <collision>
    <origin xyz="-0.15152 -0.089731 -0.128968" rpy="0 0 0"/>
    <geometry>
      <mesh filename="package://krsti_description/meshes/KAKI_KIRI_v1_1.stl" scale="0.001 0.001 0.001"/>
    </geometry>
  </collision>
</link>

<link name="KAKI_KANAN_v1_1">
  <inertial>
    <origin xyz="-0.0073672198694896135 -0.010877919789482443 -0.12320436586911505" rpy="0 0 0"/>
    <mass value="2.48851025431202"/>
    <inertia ixx="0.0210415247394198" iyy="0.0210996535444301" izz="0.00186339500713561" ixy="0.00034457571727496" iyz="-0.00301179660134896" ixz="0.000790027430121411"/>
  </inertial>
  <visual>
    <origin xyz="-0.113737 0.014641 -0.128968" rpy="0 0 0"/>
    <geometry>
      <mesh filename="package://krsti_description/meshes/KAKI_KANAN_v1_1.stl" scale="0.001 0.001 0.001"/>
    </geometry>
    <material name="steel_satin"/>
  </visual>
  <collision>
    <origin xyz="-0.113737 0.014641 -0.128968" rpy="0 0 0"/>
    <geometry>
      <mesh filename="package://krsti_description/meshes/KAKI_KANAN_v1_1.stl" scale="0.001 0.001 0.001"/>
    </geometry>
  </collision>
</link>

<joint name="Rigid 2" type="fixed">
  <origin xyz="0.113161 0.030237 0.179968" rpy="0 0 0"/>
  <parent link="base_link"/>
  <child link="pinggang_dey_1"/>
</joint>

<joint name="Revolute 5" type="continuous">
  <origin xyz="0.111644 0.098144 0.264468" rpy="0 0 0"/>
  <parent link="base_link"/>
  <child link="TANGAN_KIRI_v1_1"/>
  <axis xyz="-0.0 1.0 -0.0"/>
</joint>

<joint name="Revolute 6" type="continuous">
  <origin xyz="0.111644 -0.007856 0.264468" rpy="0 0 0"/>
  <parent link="base_link"/>
  <child link="TANGAN_KANAN_v1_1"/>
  <axis xyz="-0.0 -1.0 0.0"/>
</joint>

<joint name="Rigid 10" type="fixed">
  <origin xyz="0.038359 0.059494 -0.051" rpy="0 0 0"/>
  <parent link="pinggang_dey_1"/>
  <child link="KAKI_KIRI_v1_1"/>
</joint>

<joint name="Rigid 11" type="fixed">
  <origin xyz="0.000576 -0.044878 -0.051" rpy="0 0 0"/>
  <parent link="pinggang_dey_1"/>
  <child link="KAKI_KANAN_v1_1"/>
</joint>

</robot>
